Workbook

Sheet Base
A1: Año | B1: Mes | C1: Rutas Basicas | D1: Rutas Adicionales | E1: Descuentos | F1: Total
A2: 2024 | B2: Enero | C2: =331320679.283 -> 3.3132068e+08 | D2: =56796101 -> 56796101 | E2: 1279744 | F2: =+Tabla1[[#This Row],[Rutas Basicas]]+Tabla1[[#This Row],[Rutas Adicionales]]-Tabla1[[#This Row],[Descuentos]] -> 3.8683704e+08
A3: 2024 | B3: Febrero | C3: 3.3183204e+08 | D3: 41055689 | E3: 1903173 | F3: =+Tabla1[[#This Row],[Rutas Basicas]]+Tabla1[[#This Row],[Rutas Adicionales]]-Tabla1[[#This Row],[Descuentos]] -> 3.7098456e+08
A4: 2024 | B4: Marzo | C4: 3.4174094e+08 | D4: 38675644 | E4: 135906 | F4: =+Tabla1[[#This Row],[Rutas Basicas]]+Tabla1[[#This Row],[Rutas Adicionales]]-Tabla1[[#This Row],[Descuentos]] -> 3.8028068e+08
A5: 2024 | B5: Abril | C5: 3.439854e+08 | D5: =910000+1892000+5040000+4500000+42829489 -> 55171489 | E5: 718498 | F5: =+Tabla1[[#This Row],[Rutas Basicas]]+Tabla1[[#This Row],[Rutas Adicionales]]-Tabla1[[#This Row],[Descuentos]] -> 3.9843839e+08
A6: 2024 | B6: Mayo | C6: 3.4081684e+08 | D6: =13574783+910000 -> 14484783 | E6: 14323713 | F6: =+Tabla1[[#This Row],[Rutas Basicas]]+Tabla1[[#This Row],[Rutas Adicionales]]-Tabla1[[#This Row],[Descuentos]] -> 3.4097791e+08
A7: 2024 | B7: Junio | C7: =343821730-910000-2153846 -> 340757884 | D7: =2153846+910000+36746592.54 -> 39810439 | E7: 26616156 | F7: =+Tabla1[[#This Row],[Rutas Basicas]]+Tabla1[[#This Row],[Rutas Adicionales]]-Tabla1[[#This Row],[Descuentos]] -> 3.5395217e+08
A8: 2024 | B8: Julio | C8: =344002109-875000-2369224 -> 340757885 | D8: =40324150+875000+2369224 -> 43568374 | E8: 13230850 | F8: =+Tabla1[[#This Row],[Rutas Basicas]]+Tabla1[[#This Row],[Rutas Adicionales]]-Tabla1[[#This Row],[Descuentos]] -> 371095409
A9: 2024 | B9: Agosto | C9: 341434520 | D9: 34608727 | E9: 26461700 | F9: =+Tabla1[[#This Row],[Rutas Basicas]]+Tabla1[[#This Row],[Rutas Adicionales]]-Tabla1[[#This Row],[Descuentos]] -> 3.4958155e+08
A10: 2024 | B10: Septiembre | C10: =346226960-840000-4092315 -> 341294645 | D10: =840000+4092315+24405152.85 -> 29337468 | E10: 16453314 | F10: =+Tabla1[[#This Row],[Rutas Basicas]]+Tabla1[[#This Row],[Rutas Adicionales]]-Tabla1[[#This Row],[Descuentos]] -> 3.541788e+08
A11: 2024 | B11: Octubre | C11: =342564366-910000 -> 341654366 | D11: =910000+38073720 -> 38983720 | E11: 0 | F11: =+Tabla1[[#This Row],[Rutas Basicas]]+Tabla1[[#This Row],[Rutas Adicionales]]-Tabla1[[#This Row],[Descuentos]] -> 380638086
A12: 2024 | B12: Noviembre | C12: =350379736-840000 -> 349539736 | D12: =840000+60852276.46 -> 61692276 | E12: 27249373 | F12: =+Tabla1[[#This Row],[Rutas Basicas]]+Tabla1[[#This Row],[Rutas Adicionales]]-Tabla1[[#This Row],[Descuentos]] -> 3.8398264e+08
A13: 2024 | B13: Diciembre | C13: =356730682-3850000-875000 -> 352005682 | D13: =3850000+875000+18964274.62 -> 23689275 | E13: 14449454 | F13: =+Tabla1[[#This Row],[Rutas Basicas]]+Tabla1[[#This Row],[Rutas Adicionales]]-Tabla1[[#This Row],[Descuentos]] -> 3.612455e+08
A14: 2025 | B14: Enero | C14: =382505039.14-846860-7732200-7437390 -> 3.6648859e+08 | D14: =846860+7732200+7437390+39231195.07 -> 55247645 | E14: 15346915 | F14: =+Tabla1[[#This Row],[Rutas Basicas]]+Tabla1[[#This Row],[Rutas Adicionales]]-Tabla1[[#This Row],[Descuentos]] -> 4.0638932e+08
A15: 2025 | B15: Febrero | C15: =364752749.33-957320 -> 3.6379543e+08 | D15: =957320+14680357 -> 15637677 | E15: 34190724 | F15: =+Tabla1[[#This Row],[Rutas Basicas]]+Tabla1[[#This Row],[Rutas Adicionales]]-Tabla1[[#This Row],[Descuentos]] -> 3.4524238e+08
A16: 2025 | B16: Marzo | C16: =373100547-420795-3313800-2790000 -> 366575952 | D16: =420795+3313800+2790000+39057052 -> 45581647 | E16: 15117823 | F16: =+Tabla1[[#This Row],[Rutas Basicas]]+Tabla1[[#This Row],[Rutas Adicionales]]-Tabla1[[#This Row],[Descuentos]] -> 397039776
A17: 2025 | B17: Abril | C17: 3.6501923e+08 | D17: 78410015 | E17: 30578734 | F17: =+Tabla1[[#This Row],[Rutas Basicas]]+Tabla1[[#This Row],[Rutas Adicionales]]-Tabla1[[#This Row],[Descuentos]] -> 4.1285052e+08

Sheet Hoja1
A1: Etiquetas de fila | B1: Suma de AÑO
A2: 2025 | B2: 24300
A3: Enero | B3: 2025
A4: Febrero | B4: 2025
A5: Marzo | B5: 2025
A6: Abril | B6: 2025
A7: Mayo | B7: 2025
A8: Junio | B8: 2025
A9: Julio | B9: 2025
A10: Agosto | B10: 2025
A11: Septiembre | B11: 2025
A12: Octubre | B12: 2025
A13: Noviembre | B13: 2025
A14: Diciembre | B14: 2025
A15: (en blanco)
A16: (en blanco)
A17: Total general | B17: 24300

Sheet Base.
A1: Contratista | C1: American tours | H1: Contratista | J1: American tours | P1: PRESUPESTO MENSUAL 443
A2: AÑO | B2: MES | C2: BASICAS | D2: ADICIONALES | E2: DTOS | F2: TOTAL | G2: Columna1 | H2: AÑO | I2: MES | J2: BASICAS | K2: ADICIONALES | L2: DTOS | M2: TOTAL
A3: 2025 | B3: Enero | C3: =366488589.14-E3 -> 3.5114167e+08 | D3: 55247645 | E3: 15346915 | F3: =+C3+D3 -> 4.0638932e+08 | G3: =+D3+E3 -> 70594560 | H3: 2026 | I3: Enero | J3: 3.636681e+08 | K3: 42802614 | L3: 15346915 | M3: =+J3+K3 -> 4.0647072e+08
A4: 2025 | B4: Febrero | C4: =363795429.33-E4 -> 3.2960471e+08 | D4: 15637677 | E4: 34190724 | F4: =+C4+D4 -> 3.4524238e+08 | G4: =+D4+E4 -> 49828401 | H4: 2026 | I4: Febrero | J4: 3.3130936e+08 | K4: 16417777 | L4: 34190724 | M4: =+J4+K4 -> 3.4772714e+08
A5: 2025 | B5: Marzo | C5: =366575952-E5 -> 351458129 | D5: 45581647 | E5: 15117823 | F5: =+C5+D5 -> 397039776 | G5: =+D5+E5 -> 60699470 | H5: 2026 | I5: Marzo | J5: 3.569769e+08 | K5: 13110138 | L5: 15117823 | M5: =+J5+K5 -> 3.7008704e+08
A6: 2025 | B6: Abril | C6: =365019234.848-E6 -> 3.344405e+08 | D6: 78410015 | E6: 30578734 | F6: =+C6+D6 -> 4.1285052e+08 | G6: =+D6+E6 -> 1.0898875e+08 | H6: 2026 | I6: Abril | J6: 3.4215503e+08 | K6: 49812222 | L6: 30578734 | M6: =+J6+K6 -> 3.9196726e+08
A7: 2025 | B7: Mayo | C7: 3.6423176e+08 | D7: 15927244 | F7: =+C7+D7 -> 3.80159e+08 | G7: =+D7+E7 -> 15927244 | H7: 2026 | I7: Mayo | J7: 336768000 | K7: 936000 | M7: =+J7+K7 -> 337704000
A8: 2025 | B8: Junio | C8: 3.1543435e+08 | D8: 19650235 | F8: =+C8+D8 -> 3.3508459e+08 | G8: =+D8+E8 -> 19650235 | H8: 2026 | I8: Junio | M8: =+J8+K8 -> 0
A9: 2025 | B9: Julio | C9: 3.3867604e+08 | D9: 13924177 | F9: =+C9+D9 -> 3.5260022e+08 | G9: =+D9+E9 -> 13924177 | H9: 2026 | I9: Julio | M9: =+J9+K9 -> 0
A10: 2025 | B10: Agosto | C10: 3.1896723e+08 | D10: 20088558 | F10: =+C10+D10 -> 3.3905578e+08 | G10: =+D10+E10 -> 20088558 | H10: 2026 | I10: Agosto | M10: =+J10+K10 -> 0
A11: 2025 | B11: Septiembre | C11: 3.5881021e+08 | D11: 42704705 | F11: =+C11+D11 -> 4.0151492e+08 | G11: =+D11+E11 -> 42704705 | H11: 2026 | I11: Septiembre | M11: =+J11+K11 -> 0
A12: 2025 | B12: Octubre | C12: 3.5424283e+08 | D12: 21154406 | F12: =+C12+D12 -> 3.7539723e+08 | G12: =+D12+E12 -> 21154406 | H12: 2026 | I12: Octubre | M12: =+J12+K12 -> 0
A13: 2025 | B13: Noviembre | C13: 3.1363289e+08 | D13: 35338334 | F13: =+C13+D13 -> 3.4897122e+08 | G13: =+D13+E13 -> 35338334 | H13: 2026 | I13: Noviembre | M13: =+J13+K13 -> 0
A14: 2025 | B14: Diciembre | C14: 3.4342162e+08 | D14: 43826818 | F14: =+C14+D14 -> 3.8724844e+08 | G14: =+D14+E14 -> 43826818 | H14: 2026 | I14: Diciembre | M14: =+J14+K14 -> 0
C15: =SUBTOTAL(109,C3:C14) -> 4.0740619e+09 | D15: =SUBTOTAL(109,D3:D14) -> 4.0749146e+08 | E15: =SUBTOTAL(109,E3:E14) -> 95234196 | F15: =SUBTOTAL(109,F3:F14) -> 4.4815534e+09 | G15: =+D15+E15 -> 5.0272566e+08 | J15: =SUM(J3:J14) -> 1.7308774e+09 | K15: =SUM(K3:K14) -> 1.2307875e+08 | L15: =SUM(L3:L14) -> 95234196 | M15: =SUM(M3:M14) -> 1.8539562e+09
A18: Analisis Acumulado Abril
C19: BASICAS | D19: ADICIONALES | E19: DTOS | F19: TOTAL | H19: PROMEDIO PERSONAS | I19: COSTO POR PERSONA
A20: 2025 | C20: =SUM(C3:C7) -> 1.7308768e+09 | D20: =SUM(D3:D7) -> 2.1080423e+08 | E20: =SUM(E3:E6) -> 95234196 | F20: =SUM(F3:F7) -> 1.941681e+09 | H20: =AVERAGE('1'!C4:C7) -> 1185 | I20: =+'1'!I9 -> 326937.36
A21: 2026 | C21: =SUM(J3:J14) -> 1.7308774e+09 | D21: =SUM(K3:K14) -> 1.2307875e+08 | E21: =SUM(L3:L7) -> 95234196 | F21: =SUM(M3:M14) -> 1.8539562e+09 | G21: =SUM(N3:N7) -> 0 | H21: =AVERAGE('1'!C16:C20) -> 1136.6 | I21: =+'1'!I20 -> 326228.43
A22: Variacion | C22: =+C21/C20-1 -> 3.6781965e-07 | D22: =+D21/D20-1 -> -0.41614667 | E22: =+E21/E20-1 -> 0 | F22: =+F21/F20-1 -> -0.045179842 | G22: =+G21/G20-1 -> #DIV/0! | H22: =+H21/H20-1 -> -0.040843882 | I22: =+I21/I20-1 -> -0.002168411
B26: MES | C26: 2025 | D26: 2026 | F26: Ahorro | H26: Proyeccion | I26: Meta A Dic 2026
B27: Enero | C27: 406.38932 | D27: 406.47072 | F27: =+C27-D27 -> -0.081397732
B28: Febrero | C28: 345.24238 | D28: 347.72714 | F28: =+C28-D28 -> -2.4847582
B29: Marzo | C29: 397.03978 | D29: 370.08704 | F29: =+C29-D29 -> 26.952733
B30: Abril | C30: 412.85052 | D30: 391.96726 | F30: =+C30-D30 -> 20.883261
B31: Mayo | C31: 380 | D31: 337 | F31: =+C31-D31 -> 43
B32: TOTAL | E32: =SUM(E26:E30) -> 0 | F32: =+SUM(C27:C31)-SUM(D27:D31) -> 88.269838 | H32: =+(16.6666666666667)*5 -> 83.333333 | I32: 200

Sheet 1
A2: Contratista | D2: American tours
A3: AÑO | B3: MES | C3: N° PERSONAS | D3: BASICAS | E3: ADICIONALES | F3: TOTAL | G3: Columna1 | H3: Columna2 | I3: Columna3 | J3: Columna4
A4: 2025 | B4: Enero | C4: 1175 | D4: 3.5114167e+08 | E4: 55247645 | F4: 4.0638932e+08
A5: 2025 | B5: Febrero | C5: 1191 | D5: 3.2960471e+08 | E5: 15637677 | F5: 3.4524238e+08
A6: 2025 | B6: Marzo | C6: 1204 | D6: 351458129 | E6: 45581647 | F6: 397039776
A7: 2025 | B7: Abril | C7: 1170 | D7: 3.344405e+08 | E7: 78410015 | F7: 4.1285052e+08
A8: 2025 | B8: Mayo | C8: 1199 | D8: 3.6423176e+08 | E8: 15927244 | F8: 3.80159e+08
A9: 2025 | B9: Junio | C9: 1112 | D9: 3.1543435e+08 | E9: 19650235 | F9: 3.3508459e+08 | G9: =SUM(F4:F8) -> 1.941681e+09 | H9: =SUM(C4:C8) -> 5939 | I9: =+G9/H9 -> 326937.36
A10: 2025 | B10: Julio | C10: 1096 | D10: 3.3867604e+08 | E10: 13924177 | F10: 3.5260022e+08
A11: 2025 | B11: Agosto | C11: 1139 | D11: 3.1896723e+08 | E11: 20088558 | F11: 3.3905578e+08
A12: 2025 | B12: Septiembre | C12: 1178 | D12: 3.5881021e+08 | E12: 42704705 | F12: 4.0151492e+08
A13: 2025 | B13: Octubre | C13: 1171 | D13: 3.5424283e+08 | E13: 21154406 | F13: 3.7539723e+08
A14: 2025 | B14: Noviembre | C14: 1234 | D14: 3.1363289e+08 | E14: 35338334 | F14: 3.4897122e+08
A15: 2025 | B15: Diciembre | C15: 1198 | D15: 3.4342162e+08 | E15: 43826818 | F15: 3.8724844e+08
A16: 2026 | B16: Enero | C16: 1145 | D16: =+Base.!J3 -> 3.636681e+08 | E16: =+Base.!K3 -> 42802614 | F16: =SUM(Tabla25[[#This Row],[BASICAS]:[ADICIONALES]]) -> 4.0647072e+08
A17: 2026 | B17: Febrero | C17: 1123 | D17: =+Base.!J4 -> 3.3130936e+08 | E17: =+Base.!K4 -> 16417777 | F17: =SUM(Tabla25[[#This Row],[BASICAS]:[ADICIONALES]]) -> 3.4772714e+08
A18: 2026 | B18: Marzo | C18: 1154 | D18: =+Base.!J5 -> 3.569769e+08 | E18: =+Base.!K5 -> 13110138 | F18: =SUM(Tabla25[[#This Row],[BASICAS]:[ADICIONALES]]) -> 3.7008704e+08
A19: 2026 | B19: Abril | C19: 1130 | D19: =+Base.!J6 -> 3.4215503e+08 | E19: =+Base.!K6 -> 49812222 | F19: =SUM(Tabla25[[#This Row],[BASICAS]:[ADICIONALES]]) -> 3.9196726e+08
A20: 2026 | B20: Mayo | C20: 1131 | D20: =+Base.!J7 -> 336768000 | E20: =+Base.!K7 -> 936000 | F20: =SUM(Tabla25[[#This Row],[BASICAS]:[ADICIONALES]]) -> 337704000 | G20: =SUM(F16:F20) -> 1.8539562e+09 | H20: =SUM(C16:C20) -> 5683 | I20: =+G20/H20 -> 326228.43

Sheet Base. (2)
C1: AVANCE | D1: =+C2/B2 -> 0.4197397
A2: MCI 2026 | B2: 922 | C2: =+G19+274 -> 387 | D2: EJECUTADO | N2: PRESUPESTO MENSUAL 443
A4: Direccion Administrativa
A5: MCI 2026 Reducir los gastos operativos del ppto aprobado, pasando de 18.782 a 18.546 millones de dolares generando ahorros de 236.000 dolares a Dic 31 de 2026
F13: MES | G13: ACUMULADO MAYO | H13: META 2026 | I13: CUMPLIMIENTO
F14: NOMINA | G14: =+C58 -> 47 | H14: =+C59 -> 78 | I14: =+G14/H14 -> 0.6025641
F15: RUTAS | G15: =+D58 -> 73 | H15: =+D59 -> 200 | I15: =+G15/H15 -> 0.365
F16: ORDENES SERVICIOS | G16: =+E58 -> 8.361 | H16: =+E59 -> 23.5 | I16: =+G16/H16 -> 0.35578723
F17: PODA | G17: =+F58 -> 15.32 | H17: =+F59 -> 37 | I17: =+G17/H17 -> 0.41405405
F18: ENERGIA | G18: =+G58 -> 93.583 | H18: =+G59 -> 200 | I18: =+G18/H18 -> 0.467915
F19: INVENTARIOS | G19: =+H58 -> 113 | H19: =+H59 -> 384 | I19: =+G19/H19 -> 0.29427083
F20: TOTAL | G20: =SUM(G14:G19) -> 350.264 | H20: =SUM(H14:H19) -> 922.5 | I20: =+G20/H20 -> 0.37968997
F31: ACUMULADO A MAYO | G31: MCI | H31: ESTIMADO A MAYO | I31: EJECUTADO | K31: DIFERENCIA
F32: NOMINA | G32: =+B66 -> 78 | H32: =+C66 -> 32.5 | I32: =+D66 -> 47 | K32: =+I32-H32 -> 14.5
F33: RUTAS | G33: =+B67 -> 200 | H33: =+C67 -> 83.333333 | I33: =+D67 -> 73 | K33: =+I33-H33 -> -10.333333
F34: ORDENES SERVICIOS | G34: =+B68 -> 23.5 | H34: =+C68 -> 9.7916667 | I34: =+D68 -> 8.361 | K34: =+I34-H34 -> -1.4306667
F35: PODA | G35: =+B69 -> 37 | H35: =+C69 -> 15.416667 | I35: =+D69 -> 15.32 | K35: =+I35-H35 -> -0.096666667
F36: ENERGIA | G36: =+B70 -> 200 | H36: =+C70 -> 83.333333 | I36: =+D70 -> 93.583 | K36: =+I36-H36 -> 10.249667
F37: INVENTARIOS | G37: =+B71 -> 384 | H37: =+C71 -> 160 | I37: =+D71 -> 113 | K37: =+I37-H37 -> -47
F38: TOTAL | G38: =SUM(G32:G37) -> 922.5 | H38: =SUM(H32:H37) -> 384.375 | I38: =SUM(I32:I37) -> 350.264 | K38: =+I38-H38 -> -34.111
A44: BITACORA
A45: AÑO | B45: MES | C45: NOMINA | D45: RUTAS | E45: ORDENES SERVICIOS | F45: PODA | G45: ENERGIA | H45: INVENTARIOS | I45: TOTAL
A46: 2026 | B46: Enero | C46: 10 | D46: 0 | E46: 0.88 | F46: 3.08 | G46: 42.073 | H46: 204 | I46: =+Tabla24[[#This Row],[NOMINA]]+Tabla24[[#This Row],[RUTAS]]+Tabla24[[#This Row],[ORDENES SERVICIOS]]+Tabla24[[#This Row],[PODA]]+Tabla24[[#This Row],[ENERGIA ]] -> 56.033
A47: 2026 | B47: Febrero | C47: 15 | D47: -2 | E47: 2.452 | F47: 3.08 | H47: 200 | I47: =+Tabla24[[#This Row],[NOMINA]]+Tabla24[[#This Row],[RUTAS]]+Tabla24[[#This Row],[ORDENES SERVICIOS]]+Tabla24[[#This Row],[PODA]]+Tabla24[[#This Row],[ENERGIA ]] -> 18.532
A48: 2026 | B48: Marzo | C48: 12 | D48: 27 | E48: 0 | F48: 3.08 | G48: 39.51 | H48: 234 | I48: =+Tabla24[[#This Row],[NOMINA]]+Tabla24[[#This Row],[RUTAS]]+Tabla24[[#This Row],[ORDENES SERVICIOS]]+Tabla24[[#This Row],[PODA]]+Tabla24[[#This Row],[ENERGIA ]] -> 81.59
A49: 2026 | B49: Abril | C49: 6 | D49: 21 | E49: 0.817 | F49: 3.08 | G49: 12 | H49: 313 | I49: =+Tabla24[[#This Row],[NOMINA]]+Tabla24[[#This Row],[RUTAS]]+Tabla24[[#This Row],[ORDENES SERVICIOS]]+Tabla24[[#This Row],[PODA]]+Tabla24[[#This Row],[ENERGIA ]] -> 42.897
A50: 2026 | B50: Mayo | C50: 4 | D50: 27 | E50: 4.212 | F50: 3 | H50: 113 | I50: =+Tabla24[[#This Row],[NOMINA]]+Tabla24[[#This Row],[RUTAS]]+Tabla24[[#This Row],[ORDENES SERVICIOS]]+Tabla24[[#This Row],[PODA]]+Tabla24[[#This Row],[ENERGIA ]]+Tabla24[[#This Row],[INVENTARIOS]] -> 151.212
A51: 2026 | B51: Junio | I51: =+Tabla24[[#This Row],[NOMINA]]+Tabla24[[#This Row],[RUTAS]]+Tabla24[[#This Row],[ORDENES SERVICIOS]]+Tabla24[[#This Row],[PODA]]+Tabla24[[#This Row],[ENERGIA ]]+Tabla24[[#This Row],[INVENTARIOS]] -> 0
A52: 2026 | B52: Julio | I52: =+Tabla24[[#This Row],[NOMINA]]+Tabla24[[#This Row],[RUTAS]]+Tabla24[[#This Row],[ORDENES SERVICIOS]]+Tabla24[[#This Row],[PODA]]+Tabla24[[#This Row],[ENERGIA ]]+Tabla24[[#This Row],[INVENTARIOS]] -> 0
A53: 2026 | B53: Agosto | I53: =+Tabla24[[#This Row],[NOMINA]]+Tabla24[[#This Row],[RUTAS]]+Tabla24[[#This Row],[ORDENES SERVICIOS]]+Tabla24[[#This Row],[PODA]]+Tabla24[[#This Row],[ENERGIA ]]+Tabla24[[#This Row],[INVENTARIOS]] -> 0
A54: 2026 | B54: Septiembre | I54: =+Tabla24[[#This Row],[NOMINA]]+Tabla24[[#This Row],[RUTAS]]+Tabla24[[#This Row],[ORDENES SERVICIOS]]+Tabla24[[#This Row],[PODA]]+Tabla24[[#This Row],[ENERGIA ]]+Tabla24[[#This Row],[INVENTARIOS]] -> 0
A55: 2026 | B55: Octubre | I55: =+Tabla24[[#This Row],[NOMINA]]+Tabla24[[#This Row],[RUTAS]]+Tabla24[[#This Row],[ORDENES SERVICIOS]]+Tabla24[[#This Row],[PODA]]+Tabla24[[#This Row],[ENERGIA ]]+Tabla24[[#This Row],[INVENTARIOS]] -> 0
A56: 2026 | B56: Noviembre | I56: =+Tabla24[[#This Row],[NOMINA]]+Tabla24[[#This Row],[RUTAS]]+Tabla24[[#This Row],[ORDENES SERVICIOS]]+Tabla24[[#This Row],[PODA]]+Tabla24[[#This Row],[ENERGIA ]]+Tabla24[[#This Row],[INVENTARIOS]] -> 0
A57: 2026 | B57: Diciembre | I57: =+Tabla24[[#This Row],[NOMINA]]+Tabla24[[#This Row],[RUTAS]]+Tabla24[[#This Row],[ORDENES SERVICIOS]]+Tabla24[[#This Row],[PODA]]+Tabla24[[#This Row],[ENERGIA ]]+Tabla24[[#This Row],[INVENTARIOS]] -> 0
A58: 2026 | B58: ACUMULADO | C58: =SUBTOTAL(109,C46:C57) -> 47 | D58: =SUBTOTAL(109,D46:D57) -> 73 | E58: =SUBTOTAL(109,E46:E57) -> 8.361 | F58: =SUBTOTAL(109,F46:F57) -> 15.32 | G58: =SUBTOTAL(109,G46:G57) -> 93.583 | H58: =+H50 -> 113 | I58: =+Tabla24[[#This Row],[NOMINA]]+Tabla24[[#This Row],[RUTAS]]+Tabla24[[#This Row],[ORDENES SERVICIOS]]+Tabla24[[#This Row],[PODA]]+Tabla24[[#This Row],[ENERGIA ]]+Tabla24[[#This Row],[INVENTARIOS]] -> 350.264
A59: MCI | C59: 78 | D59: 200 | E59: 23.5 | F59: 37 | G59: 200 | H59: 384 | I59: =SUM(C59:H59) -> 922.5
A60: AVANCE MINIMO A MAYO | C60: =+C59/12*5 -> 32.5 | D60: =+D59/12*5 -> 83.333333 | E60: =+E59/12*5 -> 9.7916667 | F60: =+F59/12*5 -> 15.416667 | G60: =+G59/12*5 -> 83.333333 | H60: =+H59/12*5 -> 160 | I60: =SUM(C60:H60) -> 384.375
A65: MES | B65: MCI | C65: ESTIMADO | D65: EJECUTADO
A66: NOMINA | B66: =+H14 -> 78 | C66: =+B66/12*5 -> 32.5 | D66: =+C58 -> 47
A67: RUTAS | B67: =+H15 -> 200 | C67: =+B67/12*5 -> 83.333333 | D67: =+D58 -> 73
...

Sheet Base. (3)
C1: AVANCE | D1: =+C2/B2 -> 0.68358351
A2: MCI 2026 | B2: 922 | C2: =+C28+274 -> 630.264 | D2: EJECUTADO | N2: PRESUPESTO MENSUAL 443
A4: AÑO | B4: MES | C4: NOMINA | D4: RUTAS | E4: ORDENES SERVICIOS | F4: PODA | G4: ENERGIA | H4: INVENTARIOS | I4: TOTAL
A5: 2026 | B5: Enero | C5: 10 | D5: 0 | E5: 0.88 | F5: 3.08 | G5: 42.073 | H5: 204 | I5: =+Tabla246[[#This Row],[NOMINA]]+Tabla246[[#This Row],[RUTAS]]+Tabla246[[#This Row],[ORDENES SERVICIOS]]+Tabla246[[#This Row],[PODA]]+Tabla246[[#This Row],[ENERGIA ]] -> 56.033
A6: 2026 | B6: Febrero | C6: 15 | D6: -2 | E6: 2.452 | F6: 3.08 | H6: 200 | I6: =+Tabla246[[#This Row],[NOMINA]]+Tabla246[[#This Row],[RUTAS]]+Tabla246[[#This Row],[ORDENES SERVICIOS]]+Tabla246[[#This Row],[PODA]]+Tabla246[[#This Row],[ENERGIA ]] -> 18.532
A7: 2026 | B7: Marzo | C7: 12 | D7: 27 | E7: 0 | F7: 3.08 | G7: 39.51 | H7: 234 | I7: =+Tabla246[[#This Row],[NOMINA]]+Tabla246[[#This Row],[RUTAS]]+Tabla246[[#This Row],[ORDENES SERVICIOS]]+Tabla246[[#This Row],[PODA]]+Tabla246[[#This Row],[ENERGIA ]] -> 81.59
A8: 2026 | B8: Abril | C8: 6 | D8: 21 | E8: 0.817 | F8: 3.08 | G8: 12 | H8: 313 | I8: =+Tabla246[[#This Row],[NOMINA]]+Tabla246[[#This Row],[RUTAS]]+Tabla246[[#This Row],[ORDENES SERVICIOS]]+Tabla246[[#This Row],[PODA]]+Tabla246[[#This Row],[ENERGIA ]] -> 42.897
A9: 2026 | B9: Mayo | C9: 7 | D9: 33 | E9: 4.212 | H9: 113 | I9: =+Tabla246[[#This Row],[NOMINA]]+Tabla246[[#This Row],[RUTAS]]+Tabla246[[#This Row],[ORDENES SERVICIOS]]+Tabla246[[#This Row],[PODA]]+Tabla246[[#This Row],[ENERGIA ]]+Tabla246[[#This Row],[INVENTARIOS]] -> 157.212
A10: 2026 | B10: Junio | I10: =+Tabla246[[#This Row],[NOMINA]]+Tabla246[[#This Row],[RUTAS]]+Tabla246[[#This Row],[ORDENES SERVICIOS]]+Tabla246[[#This Row],[PODA]]+Tabla246[[#This Row],[ENERGIA ]]+Tabla246[[#This Row],[INVENTARIOS]] -> 0
A11: 2026 | B11: Julio | I11: =+Tabla246[[#This Row],[NOMINA]]+Tabla246[[#This Row],[RUTAS]]+Tabla246[[#This Row],[ORDENES SERVICIOS]]+Tabla246[[#This Row],[PODA]]+Tabla246[[#This Row],[ENERGIA ]]+Tabla246[[#This Row],[INVENTARIOS]] -> 0
A12: 2026 | B12: Agosto | I12: =+Tabla246[[#This Row],[NOMINA]]+Tabla246[[#This Row],[RUTAS]]+Tabla246[[#This Row],[ORDENES SERVICIOS]]+Tabla246[[#This Row],[PODA]]+Tabla246[[#This Row],[ENERGIA ]]+Tabla246[[#This Row],[INVENTARIOS]] -> 0
A13: 2026 | B13: Septiembre | I13: =+Tabla246[[#This Row],[NOMINA]]+Tabla246[[#This Row],[RUTAS]]+Tabla246[[#This Row],[ORDENES SERVICIOS]]+Tabla246[[#This Row],[PODA]]+Tabla246[[#This Row],[ENERGIA ]]+Tabla246[[#This Row],[INVENTARIOS]] -> 0
A14: 2026 | B14: Octubre | I14: =+Tabla246[[#This Row],[NOMINA]]+Tabla246[[#This Row],[RUTAS]]+Tabla246[[#This Row],[ORDENES SERVICIOS]]+Tabla246[[#This Row],[PODA]]+Tabla246[[#This Row],[ENERGIA ]]+Tabla246[[#This Row],[INVENTARIOS]] -> 0
A15: 2026 | B15: Noviembre | I15: =+Tabla246[[#This Row],[NOMINA]]+Tabla246[[#This Row],[RUTAS]]+Tabla246[[#This Row],[ORDENES SERVICIOS]]+Tabla246[[#This Row],[PODA]]+Tabla246[[#This Row],[ENERGIA ]]+Tabla246[[#This Row],[INVENTARIOS]] -> 0
A16: 2026 | B16: Diciembre | I16: =+Tabla246[[#This Row],[NOMINA]]+Tabla246[[#This Row],[RUTAS]]+Tabla246[[#This Row],[ORDENES SERVICIOS]]+Tabla246[[#This Row],[PODA]]+Tabla246[[#This Row],[ENERGIA ]]+Tabla246[[#This Row],[INVENTARIOS]] -> 0
C17: =SUBTOTAL(109,C5:C16) -> 50 | D17: =SUBTOTAL(109,D5:D16) -> 79 | E17: =SUBTOTAL(109,E5:E16) -> 8.361 | F17: =SUBTOTAL(109,F5:F16) -> 12.32 | G17: =SUBTOTAL(109,G5:G16) -> 93.583 | H17: =+H9 -> 113 | I17: =+Tabla246[[#This Row],[NOMINA]]+Tabla246[[#This Row],[RUTAS]]+Tabla246[[#This Row],[ORDENES SERVICIOS]]+Tabla246[[#This Row],[PODA]]+Tabla246[[#This Row],[ENERGIA ]]+Tabla246[[#This Row],[INVENTARIOS]] -> 356.264
B22: MES | C22: 2026 | D22: Proyeccion | E22: Cumplimiento | F22: Meta A Dic 2026
B23: Enero | C23: =+I5 -> 56.033 | D23: 76.83 | E23: =+C23/D23-1 -> -0.27068853
B24: Febrero | C24: =+I6 -> 18.532 | D24: 76.83 | E24: =+C24/D24-1 -> -0.75879214
B25: Marzo | C25: =+I7 -> 81.59 | D25: 76.83 | E25: =+C25/D25-1 -> 0.061954966
B26: Abril | C26: =+I8 -> 42.897 | D26: 76.83 | E26: =+C26/D26-1 -> -0.44166341
B27: Mayo | C27: =+I9 -> 157.212 | D27: 76.83 | E27: =+C27/D27-1 -> 1.0462319
B28: TOTAL | C28: =SUM(C23:C27) -> 356.264 | D28: =SUM(D23:D27) -> 384.15 | E28: =SUM(E23:E27) -> -0.36295718 | F28: 992
